2020/10/03 15:24:44 logger.go:297: Attempt 1 of http call to http://10.0.0.6:16384/sendlogstoartifacts/info
2020/10/03 15:24:44 logger.go:297: Attempt 1 of http call to http://10.0.0.6:16384/sendlogstoartifacts/status
[2020-10-03T15:24:46.005994] Entering context manager injector.
[context_manager_injector.py] Command line Options: Namespace(inject=['ProjectPythonPath:context_managers.ProjectPythonPath', 'RunHistory:context_managers.RunHistory', 'TrackUserError:context_managers.TrackUserError'], invocation=['train.py', '--C', '0.3711894041127919', '--max_iter', '150'])
Starting the daemon thread to refresh tokens in background for process with pid = 110
Entering Run History Context Manager.
Current directory:  /mnt/batch/tasks/shared/LS_root/jobs/quick-starts-ws-119614/azureml/hd_573900d3-e172-4c94-86af-57404a4302e2_3/mounts/workspaceblobstore/azureml/HD_573900d3-e172-4c94-86af-57404a4302e2_3
Preparing to call script [ train.py ] with arguments: ['--C', '0.3711894041127919', '--max_iter', '150']
After variable expansion, calling script [ train.py ] with arguments: ['--C', '0.3711894041127919', '--max_iter', '150']

Script type = None
Performing interactive authentication. Please follow the instructions on the terminal.
To sign in, use a web browser to open the page https://microsoft.com/devicelogin and enter the code R4HVXF2G3 to authenticate.
Starting the daemon thread to refresh tokens in background for process with pid = 110


The experiment failed. Finalizing run...
[2020-10-03T15:40:09.843766] TimeoutHandler __init__
[2020-10-03T15:40:09.843819] TimeoutHandler __enter__
Cleaning up all outstanding Run operations, waiting 300.0 seconds
1 items cleaning up...
Cleanup took 0.09214305877685547 seconds
[2020-10-03T15:40:10.599591] TimeoutHandler __exit__
Logging warning in history service: ERROR:: RunHistoryFinalization  failed. . Exception Details:Traceback (most recent call last):
  File "/opt/miniconda/lib/python3.6/site-packages/azureml/_base_sdk_common/common.py", line 579, in perform_interactive_login
    use_cert_sn_issuer=use_cert_sn_issuer)
  File "/opt/miniconda/lib/python3.6/site-packages/azureml/_vendor/azure_cli_core/_profile.py", line 228, in find_subscriptions_on_login
    tenant, self._ad_resource_uri)
  File "/opt/miniconda/lib/python3.6/site-packages/azureml/_vendor/azure_cli_core/_profile.py", line 786, in find_through_interactive_flow
    token_entry = context.acquire_token_with_device_code(resource, code, _CLIENT_ID)
  File "/opt/miniconda/lib/python3.6/site-packages/adal/authentication_context.py", line 311, in acquire_token_with_device_code
    return self._acquire_token(token_func, user_code_info.get('correlation_id', None))
  File "/opt/miniconda/lib/python3.6/site-packages/adal/authentication_context.py", line 128, in _acquire_token
    return token_func(self)
  File "/opt/miniconda/lib/python3.6/site-packages/adal/authentication_context.py", line 304, in token_func
    token = token_request.get_token_with_device_code(user_code_info)
  File "/opt/miniconda/lib/python3.6/site-packages/adal/token_request.py", line 392, in get_token_with_device_code
    token = client.get_token_with_polling(oauth_parameters, interval, expires_in)
  File "/opt/miniconda/lib/python3.6/site-packages/adal/oauth2_client.py", line 362, in get_token_with_polling
    wire_response)
adal.adal_error.AdalError: Unexpected polling state code_expired

During handling of the above exception, another exception occurred:

Traceback (most recent call last):
  File "/mnt/batch/tasks/shared/LS_root/jobs/quick-starts-ws-119614/azureml/hd_573900d3-e172-4c94-86af-57404a4302e2_3/mounts/workspaceblobstore/azureml/HD_573900d3-e172-4c94-86af-57404a4302e2_3/azureml-setup/context_manager_injector.py", line 170, in execute_with_context
    runpy.run_path(sys.argv[0], globals(), run_name="__main__")
  File "/opt/miniconda/lib/python3.6/runpy.py", line 263, in run_path
    pkg_name=pkg_name, script_name=fname)
  File "/opt/miniconda/lib/python3.6/runpy.py", line 96, in _run_module_code
    mod_name, mod_spec, pkg_name, script_name)
  File "/opt/miniconda/lib/python3.6/runpy.py", line 85, in _run_code
    exec(code, run_globals)
  File "train.py", line 24, in <module>
    workspace = Workspace(subscription_id, resource_group, workspace_name)
  File "/opt/miniconda/lib/python3.6/site-packages/azureml/core/workspace.py", line 178, in __init__
    auth = InteractiveLoginAuthentication()
  File "/opt/miniconda/lib/python3.6/site-packages/azureml/core/authentication.py", line 414, in __init__
    perform_interactive_login(tenant=tenant_id, cloud_type=self._cloud_type)
  File "/opt/miniconda/lib/python3.6/site-packages/azureml/_base_sdk_common/common.py", line 589, in perform_interactive_login
    raise AuthenticationException(err)
azureml.exceptions._azureml_exception.AuthenticationException: <unprintable AuthenticationException object>

During handling of the above exception, another exception occurred:

Traceback (most recent call last):
  File "/mnt/batch/tasks/shared/LS_root/jobs/quick-starts-ws-119614/azureml/hd_573900d3-e172-4c94-86af-57404a4302e2_3/mounts/workspaceblobstore/azureml/HD_573900d3-e172-4c94-86af-57404a4302e2_3/azureml-setup/context_manager_injector.py", line 201, in execute_with_context
    raise UserScriptException(baseEx).with_traceback(exceptionInfo[2])
  File "/mnt/batch/tasks/shared/LS_root/jobs/quick-starts-ws-119614/azureml/hd_573900d3-e172-4c94-86af-57404a4302e2_3/mounts/workspaceblobstore/azureml/HD_573900d3-e172-4c94-86af-57404a4302e2_3/azureml-setup/context_manager_injector.py", line 170, in execute_with_context
    runpy.run_path(sys.argv[0], globals(), run_name="__main__")
  File "/opt/miniconda/lib/python3.6/runpy.py", line 263, in run_path
    pkg_name=pkg_name, script_name=fname)
  File "/opt/miniconda/lib/python3.6/runpy.py", line 96, in _run_module_code
    mod_name, mod_spec, pkg_name, script_name)
  File "/opt/miniconda/lib/python3.6/runpy.py", line 85, in _run_code
    exec(code, run_globals)
  File "train.py", line 24, in <module>
    workspace = Workspace(subscription_id, resource_group, workspace_name)
  File "/opt/miniconda/lib/python3.6/site-packages/azureml/core/workspace.py", line 178, in __init__
    auth = InteractiveLoginAuthentication()
  File "/opt/miniconda/lib/python3.6/site-packages/azureml/core/authentication.py", line 414, in __init__
    perform_interactive_login(tenant=tenant_id, cloud_type=self._cloud_type)
  File "/opt/miniconda/lib/python3.6/site-packages/azureml/_base_sdk_common/common.py", line 589, in perform_interactive_login
    raise AuthenticationException(err)
UserScriptException: <unprintable UserScriptException object>

During handling of the above exception, another exception occurred:

Traceback (most recent call last):
  File "/mnt/batch/tasks/shared/LS_root/jobs/quick-starts-ws-119614/azureml/hd_573900d3-e172-4c94-86af-57404a4302e2_3/mounts/workspaceblobstore/azureml/HD_573900d3-e172-4c94-86af-57404a4302e2_3/azureml-setup/context_managers.py", line 281, in __exit__
    self.history_context.__exit__(*args)
  File "/opt/miniconda/lib/python3.6/site-packages/azureml/_history/utils/context_managers.py", line 56, in __exit__
    return self._exit_stack.__exit__(*args)
  File "/opt/miniconda/lib/python3.6/contextlib.py", line 380, in __exit__
    raise exc_details[1]
  File "/opt/miniconda/lib/python3.6/contextlib.py", line 365, in __exit__
    if cb(*exc_details):
  File "/opt/miniconda/lib/python3.6/contextlib.py", line 284, in _exit_wrapper
    return cm_exit(cm, *exc_details)
  File "/opt/miniconda/lib/python3.6/site-packages/azureml/_history/utils/log_scope.py", line 30, in __exit__
    self._logger.error("{0}: {1}\n{2}".format(etype, value, traceback))
  File "/opt/miniconda/lib/python3.6/site-packages/azureml/_common/exceptions.py", line 116, in __str__
    return self.__repr__()
  File "/opt/miniconda/lib/python3.6/site-packages/azureml/_common/exceptions.py", line 112, in __repr__
    self._serialize_json(indent=4))
  File "/opt/miniconda/lib/python3.6/site-packages/azureml/_common/exceptions.py", line 183, in _serialize_json
    return json.dumps(error_ret, indent=indent)
  File "/opt/miniconda/lib/python3.6/json/__init__.py", line 238, in dumps
    **kw).encode(obj)
  File "/opt/miniconda/lib/python3.6/json/encoder.py", line 201, in encode
    chunks = list(chunks)
  File "/opt/miniconda/lib/python3.6/json/encoder.py", line 430, in _iterencode
    yield from _iterencode_dict(o, _current_indent_level)
  File "/opt/miniconda/lib/python3.6/json/encoder.py", line 404, in _iterencode_dict
    yield from chunks
  File "/opt/miniconda/lib/python3.6/json/encoder.py", line 404, in _iterencode_dict
    yield from chunks
  File "/opt/miniconda/lib/python3.6/json/encoder.py", line 437, in _iterencode
    o = _default(o)
  File "/opt/miniconda/lib/python3.6/json/encoder.py", line 180, in default
    o.__class__.__name__)
TypeError: Object of type 'AdalError' is not JSON serializable

Traceback (most recent call last):
  File "/opt/miniconda/lib/python3.6/site-packages/azureml/_base_sdk_common/common.py", line 579, in perform_interactive_login
    use_cert_sn_issuer=use_cert_sn_issuer)
  File "/opt/miniconda/lib/python3.6/site-packages/azureml/_vendor/azure_cli_core/_profile.py", line 228, in find_subscriptions_on_login
    tenant, self._ad_resource_uri)
  File "/opt/miniconda/lib/python3.6/site-packages/azureml/_vendor/azure_cli_core/_profile.py", line 786, in find_through_interactive_flow
    token_entry = context.acquire_token_with_device_code(resource, code, _CLIENT_ID)
  File "/opt/miniconda/lib/python3.6/site-packages/adal/authentication_context.py", line 311, in acquire_token_with_device_code
    return self._acquire_token(token_func, user_code_info.get('correlation_id', None))
  File "/opt/miniconda/lib/python3.6/site-packages/adal/authentication_context.py", line 128, in _acquire_token
    return token_func(self)
  File "/opt/miniconda/lib/python3.6/site-packages/adal/authentication_context.py", line 304, in token_func
    token = token_request.get_token_with_device_code(user_code_info)
  File "/opt/miniconda/lib/python3.6/site-packages/adal/token_request.py", line 392, in get_token_with_device_code
    token = client.get_token_with_polling(oauth_parameters, interval, expires_in)
  File "/opt/miniconda/lib/python3.6/site-packages/adal/oauth2_client.py", line 362, in get_token_with_polling
    wire_response)
adal.adal_error.AdalError: Unexpected polling state code_expired

During handling of the above exception, another exception occurred:

Traceback (most recent call last):
  File "/mnt/batch/tasks/shared/LS_root/jobs/quick-starts-ws-119614/azureml/hd_573900d3-e172-4c94-86af-57404a4302e2_3/mounts/workspaceblobstore/azureml/HD_573900d3-e172-4c94-86af-57404a4302e2_3/azureml-setup/context_manager_injector.py", line 170, in execute_with_context
    runpy.run_path(sys.argv[0], globals(), run_name="__main__")
  File "/opt/miniconda/lib/python3.6/runpy.py", line 263, in run_path
    pkg_name=pkg_name, script_name=fname)
  File "/opt/miniconda/lib/python3.6/runpy.py", line 96, in _run_module_code
    mod_name, mod_spec, pkg_name, script_name)
  File "/opt/miniconda/lib/python3.6/runpy.py", line 85, in _run_code
    exec(code, run_globals)
  File "train.py", line 24, in <module>
    workspace = Workspace(subscription_id, resource_group, workspace_name)
  File "/opt/miniconda/lib/python3.6/site-packages/azureml/core/workspace.py", line 178, in __init__
    auth = InteractiveLoginAuthentication()
  File "/opt/miniconda/lib/python3.6/site-packages/azureml/core/authentication.py", line 414, in __init__
    perform_interactive_login(tenant=tenant_id, cloud_type=self._cloud_type)
  File "/opt/miniconda/lib/python3.6/site-packages/azureml/_base_sdk_common/common.py", line 589, in perform_interactive_login
    raise AuthenticationException(err)
azureml.exceptions._azureml_exception.AuthenticationException: <unprintable AuthenticationException object>

During handling of the above exception, another exception occurred:

Traceback (most recent call last):
  File "/mnt/batch/tasks/shared/LS_root/jobs/quick-starts-ws-119614/azureml/hd_573900d3-e172-4c94-86af-57404a4302e2_3/mounts/workspaceblobstore/azureml/HD_573900d3-e172-4c94-86af-57404a4302e2_3/azureml-setup/context_manager_injector.py", line 201, in execute_with_context
    raise UserScriptException(baseEx).with_traceback(exceptionInfo[2])
  File "/mnt/batch/tasks/shared/LS_root/jobs/quick-starts-ws-119614/azureml/hd_573900d3-e172-4c94-86af-57404a4302e2_3/mounts/workspaceblobstore/azureml/HD_573900d3-e172-4c94-86af-57404a4302e2_3/azureml-setup/context_manager_injector.py", line 170, in execute_with_context
    runpy.run_path(sys.argv[0], globals(), run_name="__main__")
  File "/opt/miniconda/lib/python3.6/runpy.py", line 263, in run_path
    pkg_name=pkg_name, script_name=fname)
  File "/opt/miniconda/lib/python3.6/runpy.py", line 96, in _run_module_code
    mod_name, mod_spec, pkg_name, script_name)
  File "/opt/miniconda/lib/python3.6/runpy.py", line 85, in _run_code
    exec(code, run_globals)
  File "train.py", line 24, in <module>
    workspace = Workspace(subscription_id, resource_group, workspace_name)
  File "/opt/miniconda/lib/python3.6/site-packages/azureml/core/workspace.py", line 178, in __init__
    auth = InteractiveLoginAuthentication()
  File "/opt/miniconda/lib/python3.6/site-packages/azureml/core/authentication.py", line 414, in __init__
    perform_interactive_login(tenant=tenant_id, cloud_type=self._cloud_type)
  File "/opt/miniconda/lib/python3.6/site-packages/azureml/_base_sdk_common/common.py", line 589, in perform_interactive_login
    raise AuthenticationException(err)
UserScriptException: <unprintable UserScriptException object>

During handling of the above exception, another exception occurred:

Traceback (most recent call last):
  File "train.py", line 24, in <module>
    workspace = Workspace(subscription_id, resource_group, workspace_name)
  File "/opt/miniconda/lib/python3.6/site-packages/azureml/core/workspace.py", line 178, in __init__
    auth = InteractiveLoginAuthentication()
  File "/opt/miniconda/lib/python3.6/site-packages/azureml/core/authentication.py", line 414, in __init__
    perform_interactive_login(tenant=tenant_id, cloud_type=self._cloud_type)
  File "/opt/miniconda/lib/python3.6/site-packages/azureml/_base_sdk_common/common.py", line 589, in perform_interactive_login
    raise AuthenticationException(err)
UserScriptException: <unprintable UserScriptException object>

During handling of the above exception, another exception occurred:

Traceback (most recent call last):
  File "/mnt/batch/tasks/shared/LS_root/jobs/quick-starts-ws-119614/azureml/hd_573900d3-e172-4c94-86af-57404a4302e2_3/mounts/workspaceblobstore/azureml/HD_573900d3-e172-4c94-86af-57404a4302e2_3/azureml-setup/context_manager_injector.py", line 313, in <module>
    execute_with_context(cm_objects, options.invocation)
  File "/mnt/batch/tasks/shared/LS_root/jobs/quick-starts-ws-119614/azureml/hd_573900d3-e172-4c94-86af-57404a4302e2_3/mounts/workspaceblobstore/azureml/HD_573900d3-e172-4c94-86af-57404a4302e2_3/azureml-setup/context_manager_injector.py", line 218, in execute_with_context
    print("Error occurred when setting run status to Finalizing: {}".format(ex))
  File "/mnt/batch/tasks/shared/LS_root/jobs/quick-starts-ws-119614/azureml/hd_573900d3-e172-4c94-86af-57404a4302e2_3/mounts/workspaceblobstore/azureml/HD_573900d3-e172-4c94-86af-57404a4302e2_3/azureml-setup/_vendor_contextlib2.py", line 393, in __exit__
    _reraise_with_existing_context(exc_details)
  File "/mnt/batch/tasks/shared/LS_root/jobs/quick-starts-ws-119614/azureml/hd_573900d3-e172-4c94-86af-57404a4302e2_3/mounts/workspaceblobstore/azureml/HD_573900d3-e172-4c94-86af-57404a4302e2_3/azureml-setup/_vendor_contextlib2.py", line 261, in _reraise_with_existing_context
    raise exc_details[1]
  File "/mnt/batch/tasks/shared/LS_root/jobs/quick-starts-ws-119614/azureml/hd_573900d3-e172-4c94-86af-57404a4302e2_3/mounts/workspaceblobstore/azureml/HD_573900d3-e172-4c94-86af-57404a4302e2_3/azureml-setup/_vendor_contextlib2.py", line 382, in __exit__
    if cb(*exc_details):
  File "/mnt/batch/tasks/shared/LS_root/jobs/quick-starts-ws-119614/azureml/hd_573900d3-e172-4c94-86af-57404a4302e2_3/mounts/workspaceblobstore/azureml/HD_573900d3-e172-4c94-86af-57404a4302e2_3/azureml-setup/_vendor_contextlib2.py", line 314, in _exit_wrapper
    return cm_exit(cm, *exc_details)
  File "/mnt/batch/tasks/shared/LS_root/jobs/quick-starts-ws-119614/azureml/hd_573900d3-e172-4c94-86af-57404a4302e2_3/mounts/workspaceblobstore/azureml/HD_573900d3-e172-4c94-86af-57404a4302e2_3/azureml-setup/context_manager_injector.py", line 69, in __exit__
    self.context_manager.__exit__(*exc_details)
  File "/mnt/batch/tasks/shared/LS_root/jobs/quick-starts-ws-119614/azureml/hd_573900d3-e172-4c94-86af-57404a4302e2_3/mounts/workspaceblobstore/azureml/HD_573900d3-e172-4c94-86af-57404a4302e2_3/azureml-setup/context_managers.py", line 281, in __exit__
    self.history_context.__exit__(*args)
  File "/opt/miniconda/lib/python3.6/site-packages/azureml/_history/utils/context_managers.py", line 56, in __exit__
    return self._exit_stack.__exit__(*args)
  File "/opt/miniconda/lib/python3.6/contextlib.py", line 380, in __exit__
    raise exc_details[1]
  File "/opt/miniconda/lib/python3.6/contextlib.py", line 365, in __exit__
    if cb(*exc_details):
  File "/opt/miniconda/lib/python3.6/contextlib.py", line 284, in _exit_wrapper
    return cm_exit(cm, *exc_details)
  File "/opt/miniconda/lib/python3.6/site-packages/azureml/_history/utils/log_scope.py", line 30, in __exit__
    self._logger.error("{0}: {1}\n{2}".format(etype, value, traceback))
  File "/opt/miniconda/lib/python3.6/site-packages/azureml/_common/exceptions.py", line 116, in __str__
    return self.__repr__()
  File "/opt/miniconda/lib/python3.6/site-packages/azureml/_common/exceptions.py", line 112, in __repr__
    self._serialize_json(indent=4))
  File "/opt/miniconda/lib/python3.6/site-packages/azureml/_common/exceptions.py", line 183, in _serialize_json
    return json.dumps(error_ret, indent=indent)
  File "/opt/miniconda/lib/python3.6/json/__init__.py", line 238, in dumps
    **kw).encode(obj)
  File "/opt/miniconda/lib/python3.6/json/encoder.py", line 201, in encode
    chunks = list(chunks)
  File "/opt/miniconda/lib/python3.6/json/encoder.py", line 430, in _iterencode
    yield from _iterencode_dict(o, _current_indent_level)
  File "/opt/miniconda/lib/python3.6/json/encoder.py", line 404, in _iterencode_dict
    yield from chunks
  File "/opt/miniconda/lib/python3.6/json/encoder.py", line 404, in _iterencode_dict
    yield from chunks
  File "/opt/miniconda/lib/python3.6/json/encoder.py", line 437, in _iterencode
    o = _default(o)
  File "/opt/miniconda/lib/python3.6/json/encoder.py", line 180, in default
    o.__class__.__name__)
TypeError: Object of type 'AdalError' is not JSON serializable

2020/10/03 15:40:11 logger.go:297: Failed to run the wrapper cmd with err: exit status 1
2020/10/03 15:40:11 logger.go:297: Attempt 1 of http call to http://10.0.0.6:16384/sendlogstoartifacts/status
2020/10/03 15:40:11 sysutils_linux.go:221: mpirun version string: {
Intel(R) MPI Library for Linux* OS, Version 2018 Update 3 Build 20180411 (id: 18329)
Copyright 2003-2018 Intel Corporation.
}
2020/10/03 15:40:11 sysutils_linux.go:225: MPI publisher: intel ; version: 2018
2020/10/03 15:40:11 logger.go:297: Process Exiting with Code:  1
